Workbook

Sheet Raw data
A1: Replicate of Drug Treatment | B1: images_per_sponge | D1: species | E1: spicules | F1: PDMPO | G1: proportion_of_spicules_w_PDMPO
A2: DMSO1 | B2: 1 | C2: DMSO1_1 | D2: E. muelleri | E2: 21 | F2: 21 | G2: =F2/E2 -> 1
A3: DMSO1 | B3: 2 | C3: DMSO1_2 | D3: E. muelleri | E3: 16 | F3: 15 | G3: =F3/E3 -> 0.9375
A4: DMSO1 | B4: 3 | C4: DMSO1_3 | D4: E. muelleri | E4: 25 | F4: 21 | G4: =F4/E4 -> 0.84
A5: DMSO1 | B5: 4 | C5: DMSO1_4 | D5: E. muelleri | E5: 28 | F5: 26 | G5: =F5/E5 -> 0.92857143
A6: DMSO1 | B6: 5 | C6: DMSO1_5 | D6: E. muelleri | E6: 27 | F6: 27 | G6: =F6/E6 -> 1
A7: DMSO1_avg | D7: E. muelleri | E7: =AVERAGE(E2:E6) -> 23.4 | F7: =AVERAGE(F2:F6) -> 22 | G7: =AVERAGE(G2:G6) -> 0.94121429
A8: DMSO2 | B8: 1 | C8: DMSO2_1 | D8: E. muelleri | E8: 24 | F8: 22 | G8: =F8/E8 -> 0.91666667
A9: DMSO2 | B9: 2 | C9: DMSO2_2 | D9: E. muelleri | E9: 15 | F9: 15 | G9: =F9/E9 -> 1
A10: DMSO2 | B10: 3 | C10: DMSO2_3 | D10: E. muelleri | E10: 12 | F10: 6 | G10: =F10/E10 -> 0.5
A11: DMSO2 | B11: 4 | C11: DMSO2_4 | D11: E. muelleri | E11: 13 | F11: 12 | G11: =F11/E11 -> 0.92307692
A12: DMSO2 | B12: 5 | C12: DMSO2_5 | D12: E. muelleri | E12: 18 | F12: 15 | G12: =F12/E12 -> 0.83333333
A13: DMSO2_avg | D13: E. muelleri | E13: =AVERAGE(E8:E12) -> 16.4 | F13: =AVERAGE(F8:F12) -> 14 | G13: =AVERAGE(G8:G12) -> 0.83461538
A14: DMSO3 | B14: 1 | C14: DMSO3_1 | D14: E. muelleri | E14: 17 | F14: 13 | G14: =F14/E14 -> 0.76470588
A15: DMSO3 | B15: 2 | C15: DMSO3_2 | D15: E. muelleri | E15: 16 | F15: 16 | G15: =F15/E15 -> 1
A16: DMSO3 | B16: 3 | C16: DMSO3_3 | D16: E. muelleri | E16: 19 | F16: 13 | G16: =F16/E16 -> 0.68421053
A17: DMSO3 | B17: 4 | C17: DMSO3_4 | D17: E. muelleri | E17: 13 | F17: 11 | G17: =F17/E17 -> 0.84615385
A18: DMSO3 | B18: 5 | C18: DMSO3_5 | D18: E. muelleri | E18: 20 | F18: 15 | G18: =F18/E18 -> 0.75
A19: DMSO3_avg | D19: E. muelleri | E19: =AVERAGE(E14:E18) -> 17 | F19: =AVERAGE(F14:F18) -> 13.6 | G19: =AVERAGE(G14:G18) -> 0.80901405
A20: DMSO4 | B20: 1 | C20: DMSO4_1 | D20: E. muelleri | E20: 15 | F20: 14 | G20: =F20/E20 -> 0.93333333
A21: DMSO4 | B21: 2 | C21: DMSO4_2 | D21: E. muelleri | E21: 19 | F21: 18 | G21: =F21/E21 -> 0.94736842
A22: DMSO4 | B22: 3 | C22: DMSO4_3 | D22: E. muelleri | E22: 14 | F22: 14 | G22: =F22/E22 -> 1
A23: DMSO4 | B23: 4 | C23: DMSO4_4 | D23: E. muelleri | E23: 8 | F23: 7 | G23: =F23/E23 -> 0.875
A24: DMSO4 | B24: 5 | C24: DMSO4_5 | D24: E. muelleri | E24: 18 | F24: 13 | G24: =F24/E24 -> 0.72222222
A25: DMSO4_avg | D25: E. muelleri | E25: =AVERAGE(E20:E24) -> 14.8 | F25: =AVERAGE(F20:F24) -> 13.2 | G25: =AVERAGE(G20:G24) -> 0.8955848
A26: concA1 | B26: 1 | C26: concA1_1 | D26: E. muelleri | E26: 11 | F26: 1 | G26: =F26/E26 -> 0.090909091
A27: concA1 | B27: 2 | C27: concA1_2 | D27: E. muelleri | E27: 6 | F27: 1 | G27: =F27/E27 -> 0.16666667
A28: concA1 | B28: 3 | C28: concA1_3 | D28: E. muelleri | E28: 6 | F28: 0 | G28: =F28/E28 -> 0
A29: concA1 | B29: 4 | C29: concA1_4 | D29: E. muelleri | E29: 6 | F29: 1 | G29: =F29/E29 -> 0.16666667
A30: concA1 | B30: 5 | C30: concA1_5 | D30: E. muelleri | E30: 9 | F30: 0 | G30: =F30/E30 -> 0
A31: concA1_avg | D31: E. muelleri | E31: =AVERAGE(E26:E30) -> 7.6 | F31: =AVERAGE(F26:F30) -> 0.6 | G31: =AVERAGE(G26:G30) -> 0.084848485
A32: concA2 | B32: 1 | C32: concA2_1 | D32: E. muelleri | E32: 13 | F32: 0 | G32: =F32/E32 -> 0
A33: concA2 | B33: 2 | C33: concA2_2 | D33: E. muelleri | E33: 16 | F33: 0 | G33: =F33/E33 -> 0
A34: concA2 | B34: 3 | C34: concA2_3 | D34: E. muelleri | E34: 12 | F34: 1 | G34: =F34/E34 -> 0.083333333
A35: concA2 | B35: 4 | C35: concA2_4 | D35: E. muelleri | E35: 18 | F35: 1 | G35: =F35/E35 -> 0.055555556
A36: concA2 | B36: 5 | C36: concA2_5 | D36: E. muelleri | E36: 15 | F36: 0 | G36: =F36/E36 -> 0
A37: concA2_avg | D37: E. muelleri | E37: =AVERAGE(E32:E36) -> 14.8 | F37: =AVERAGE(F32:F36) -> 0.4 | G37: =AVERAGE(G32:G36) -> 0.027777778
A38: concA3 | B38: 1 | C38: concA3_1 | D38: E. muelleri | E38: 9 | F38: 3 | G38: =F38/E38 -> 0.33333333
A39: concA3 | B39: 2 | C39: concA3_2 | D39: E. muelleri | E39: 14 | F39: 2 | G39: =F39/E39 -> 0.14285714
A40: concA3 | B40: 3 | C40: concA3_3 | D40: E. muelleri | E40: 6 | F40: 1 | G40: =F40/E40 -> 0.16666667
...

Sheet Summary
A1: Species | B1: Treatment | C1: Average spicules | D1: SE average spicules | E1: Average proportion of spicules w PDMPO | F1: SE average proportion of spicules w PDMPO | G1: Percentage diff in no. of spicules between DMSO and concA | H1: SE no. of spicules between DMSO and concA | I1: Percentage diff in proportion of spicules w PDMPO between DMSO and concA | J1: SE proportion of spicules w PDMPO between DMSO and concA
A2: E. muelleri | B2: DMSO | C2: =AVERAGE('Raw data'!E7,'Raw data'!E13,'Raw data'!E19,'Raw data'!E25) -> 17.9 | D2: =STDEV('Raw data'!E7,'Raw data'!E13,'Raw data'!E19,'Raw data'!E25)/(SQRT(COUNT('Raw data'!E7,'Raw data'!E13,'Raw data'!E19,'Raw data'!E25))) -> 1.8912077 | E2: =AVERAGE('Raw data'!G7,'Raw data'!G13,'Raw data'!G19,'Raw data'!G25) -> 0.87010713 | F2: =STDEV('Raw data'!G7,'Raw data'!G13,'Raw data'!G19,'Raw data'!G25)/(SQRT(COUNT('Raw data'!G7,'Raw data'!G13,'Raw data'!G19,'Raw data'!G25))) -> 0.029857114
A3: E. muelleri | B3: concA | C3: =AVERAGE('Raw data'!E31,'Raw data'!E37,'Raw data'!E43,'Raw data'!E49) -> 10.45 | D3: =STDEV('Raw data'!E31,'Raw data'!E37,'Raw data'!E43,'Raw data'!E49)/(SQRT(COUNT('Raw data'!E31,'Raw data'!E37,'Raw data'!E43,'Raw data'!E49))) -> 1.5326991 | E3: =AVERAGE('Raw data'!G31,'Raw data'!G37,'Raw data'!G43,'Raw data'!G49) -> 0.12365801 | F3: =STDEV('Raw data'!G31,'Raw data'!G37,'Raw data'!G43,'Raw data'!G49)/(SQRT(COUNT('Raw data'!G31,'Raw data'!G37,'Raw data'!G43,'Raw data'!G49))) -> 0.041009061 | G3: =(C2-C3)/C2*100 -> 41.620112 | H3: =SQRT((D3/C2)^2+((C3*D2)/(C2^2))^2)*100 -> 10.55285 | I3: =(E2-E3)/E2*100 -> 85.788186 | J3: =SQRT((F3/E2)^2+((E3*F2)/(E2^2))^2)*100 -> 4.7382674
A4: S. lacustris | B4: DMSO | C4: =AVERAGE('Raw data'!E55,'Raw data'!E61,'Raw data'!E67) -> 13.666667 | D4: =STDEV('Raw data'!E55,'Raw data'!E61,'Raw data'!E67)/(SQRT(COUNT('Raw data'!E55,'Raw data'!E61,'Raw data'!E67))) -> 0.96838927 | E4: =AVERAGE('Raw data'!G55,'Raw data'!G61,'Raw data'!G67) -> 0.80937137 | F4: =STDEV('Raw data'!G55,'Raw data'!G61,'Raw data'!G67)/(SQRT(COUNT('Raw data'!G55,'Raw data'!G61,'Raw data'!G67))) -> 0.052372419
A5: S. lacustris | B5: concA | C5: =AVERAGE('Raw data'!E74,'Raw data'!E80,'Raw data'!E86) -> 3.0777778 | D5: =STDEV('Raw data'!E74,'Raw data'!E80,'Raw data'!E86)/(SQRT(COUNT('Raw data'!E74,'Raw data'!E80,'Raw data'!E86))) -> 0.9436598 | E5: =AVERAGE('Raw data'!G74,'Raw data'!G80,'Raw data'!G86) -> 0.013888889 | F5: =STDEV('Raw data'!G74,'Raw data'!G80,'Raw data'!G86)/(SQRT(COUNT('Raw data'!G74,'Raw data'!G80,'Raw data'!G86))) -> 0.013888889 | G5: =(C4-C5)/C4*100 -> 77.479675 | H5: =SQRT((D5/C4)^2+((C5*D4)/(C4^2))^2)*100 -> 7.086821 | I5: =(E4-E5)/E4*100 -> 98.283991 | J5: =SQRT((F5/E4)^2+((E5*F4)/(E4^2))^2)*100 -> 1.7195982
